Workbook

Sheet Daily Cost Tracker
A1: Date | B1: AWS Service | C1: Operation Description | D1: Units Used | E1: Unit Cost ($) | F1: Total Cost ($) | G1: Notes/Learnings
A2: 45664 | B2: S3 | C2: Upload test documents | D2: 10 | E2: 0.005 | F2: =D2*E2 -> 0.05 | G2: Uploaded 10 sample invoices
A3: 45664 | B3: Textract | C3: OCR processing - invoices | D3: 15 | E3: 0.15 | F3: =D3*E3 -> 2.25 | G3: Tested on various invoice formats
A4: 45665 | B4: Lambda | C4: Document processing function | D4: 50 | E4: 2e-07 | F4: =D4*E4 -> 1e-05 | G4: Testing trigger from S3
A5: 45665 | B5: Comprehend | C5: Entity extraction | D5: 25 | E5: 0.0001 | F5: =D5*E5 -> 0.0025 | G5: Extracting vendor names, amounts
A7: TOTAL DEVELOPMENT COST | F7: =SUM(F2:F5) -> 2.30251

Sheet Cost Summary
A1: AWS Document Processing Pipeline - Cost Summary
A3: Development Phase Summary
A5: Category | B5: Estimated ($) | C5: Actual ($) | D5: Variance ($) | F5: Phase 3 Costs:
A6: S3 Storage | B6: 0.5 | C6: =SUMIF('Daily Cost Tracker'!B:B,"S3",'Daily Cost Tracker'!F:F) -> 0.05 | D6: =C6-B6 -> -0.45
A7: Lambda Functions | B7: 2 | C7: =SUMIF('Daily Cost Tracker'!B:B,"Lambda",'Daily Cost Tracker'!F:F) -> 1e-05 | D7: =C7-B7 -> -1.99999 | F7: Date | G7: Phase | H7: Service | I7: Resource | J7: Usage | K7: Cost | L7: Notes
A8: Textract | B8: 7.5 | C8: =SUMIF('Daily Cost Tracker'!B:B,"Textract",'Daily Cost Tracker'!F:F) -> 2.25 | D8: =C8-B8 -> -5.25 | F8: 46053 | G8: Phase 3 | H8: S3 | I8: Uploads | J8: 15 documents | K8: 0 | L8: Within Free Tier
A9: Comprehend | B9: 0.5 | C9: =SUMIF('Daily Cost Tracker'!B:B,"Comprehend",'Daily Cost Tracker'!F:F) -> 0.0025 | D9: =C9-B9 -> -0.4975 | F9: 46053 | G9: Phase 3 | H9: Lambda | I9: DocumentProcessor | J9: 15 invocations | K9: 0 | L9: Within Free Tier
A10: API Gateway | B10: 0.1 | C10: =SUMIF('Daily Cost Tracker'!B:B,"API Gateway",'Daily Cost Tracker'!F:F) -> 0 | D10: =C10-B10 -> -0.1 | F10: 46053 | G10: Phase 3 | H10: Textract | I10: AnalyzeDocument | J10: 12 pages | K10: 0 | L10: Within 1,000 page Free Tier
A11: CloudWatch | B11: 0.5 | C11: =SUMIF('Daily Cost Tracker'!B:B,"CloudWatch",'Daily Cost Tracker'!F:F) -> 0 | D11: =C11-B11 -> -0.5 | F11: 46053 | G11: Phase 3 | H11: Comprehend | I11: Entity Detection | J11: 12 documents | K11: 0.013 | L11: Within 50K unit Free Tier
A12: Other Services | B12: 0 | C12: =SUMIF('Daily Cost Tracker'!B:B,"Other",'Daily Cost Tracker'!F:F) -> 0 | D12: =C12-B12 -> 0 | F12: 46053 | G12: Phase 3 | H12: Comprehend | I12: Sentiment Analysis | J12: 12 documents | K12: 0.013 | L12: Within 50K unit Free Tier
A13: Lambda (Tag Audit) | B13: 0 | C13: =SUMIFS('Daily Cost Tracker'!F:F,'Daily Cost Tracker'!B:B,"Lambda",'Daily Cost Tracker'!C:C,"*Tag Audit*") -> 0 | D13: =C13-B13 -> 0 | F13: 46053 | G13: Phase 3 | H13: Comprehend | I13: Key Phrases | J13: 12 documents | K13: 0.012 | L13: Within 50K unit Free Tier
A14: EventBridge | B14: 0 | C14: =SUMIF('Daily Cost Tracker'!B:B,"EventBridge",'Daily Cost Tracker'!F:F) -> 0 | D14: =C14-B14 -> 0 | J14: Phase 3 Total | K14: 0.038
A15: TOTAL | B15: =SUM(B6:B14) -> 11.1 | C15: =SUM(C6:C14) -> 2.30251 | D15: =C15-B15 -> -8.79749
F16: Cumulative Project Costs:
A18: Monthly Production Cost Model (500 documents) | F18: Phase | G18: Time | H18: Cost | I18: Budget Remaining
F19: Pre-Dev Setup | G19: 1 hour | H19: 0 | I19: 25
A20: Service | B20: Usage | C20: Unit Cost | D20: Monthly Cost ($) | F20: Phase 1: S3 Infrastructure | G20: 2 hours | H20: 0 | I20: 25
A21: S3 Storage | B21: 50 GB | C21: $0.023/GB | D21: 1.15 | F21: Side Quest: Tag Governance | G21: 1 hour | H21: 0 | I21: 25
A22: S3 Requests | B22: 3,000 requests | C22: $0.005/1K PUT | D22: 0.01 | F22: Phase 3: Textract Testing | G22: 3 hours | H22: 0.038 | I22: 24.96
A23: Lambda | B23: 1,500 invocations | C23: $0.0000166667/GB-sec | D23: 1.25 | F23: Total | G23: 7 hours | H23: 0.038 | I23: 24.96
A24: Textract | B24: 1,000 pages | C24: $1.50/1K pages | D24: 1.5
A25: Comprehend | B25: 100,000 units | C25: $0.0001/unit | D25: 10
A26: API Gateway | B26: 1,500 requests | C26: $3.50/million | D26: 0.01
A27: CloudWatch Logs | B27: 5 GB | C27: $0.50/GB | D27: 2
A28: Lambda (Tag Audit) | B28: 4 invocations/month | C28: Free Tier | D28: 0
A29: EventBridge (Scheduled) | B29: 1 rule | C29: Free Tier | D29: 0
A30: Data Transfer | B30: 10 GB out | C30: $0.09/GB | D30: =SUM(D19:D29) -> 15.92
A31: MONTHLY TOTAL | D31: =SUM(D19:D26) -> 13.92
A32: ANNUAL COST | D32: =D27*12 -> 24
A35: ROI Analysis
B37: Manual Process | C37: Automated Process
A38: Monthly staff time (hours) | B38: 25 | C38: 4.2
A39: Hourly rate | B39: 25 | C39: 25
A40: Monthly labor cost | B40: 0 | C40: =D27 -> 2
A41: Monthly AWS cost | B41: 0 | C41: =D27 -> 2
A42: TOTAL MONTHLY COST | B42: =B35 -> 0 | C42: =C35+C36 -> 0
A44: Monthly Savings | B44: 0 | C44: =B44*12 -> 0
A45: Annual Savings | C45: =C39*12 -> 300
A46: ROI % | C46: =(C40/D27)/12*100 -> 8.3333333
A49: Tag Governance Solution Comparison
...

Sheet Cost Alert Setup
A1: AWS Cost Explorer & Budget Alert Setup Guide
A3: Step 1: Enable Cost Explorer
A4: 1. Log into AWS Console
A5: 2. Navigate to: Billing Dashboard > Cost Explorer
A6: 3. Click 'Enable Cost Explorer'
A7: 4. Wait 24 hours for data population
A9: Step 2: Create Budget Alert
A10: 1. Go to: Billing Dashboard > Budgets
A11: 2. Click 'Create budget'
A12: 3. Select 'Monthly cost budget'
A13: 4. Set budget amount: $25.00 (recommended)
A14: 5. Set alert threshold: 80% ($20.00)
... A23: Recommended Alert Thresholds:
A24: • 50% of budget: Warning email | B24: Helps catch runaway costs early
A25: • 80% of budget: Alert email | B25: Time to review usage
A26: • 100% of budget: Critical alert | B26: Stop non-essential testing
A28: Free Tier Limits to Monitor:
A29: • Lambda: 1M requests/month | B29: Track in Cost Explorer
A30: • Textract: 1,000 pages/month (3 months) | B30: Keep count in tracker
A31: • Comprehend: 50K units/month (12 months) | B31: Monitor usage closely
A32: • S3: 5GB storage, 20K GET, 2K PUT | B32: Check S3 metrics
